Workbook

Sheet Datos_panel_limpios
A1: País | B1: Código país | C1: Año | D1: GDP per capita, PPP (constant 2021 international $) | E1: Government Effectiveness: Estimate | F1: Government expenditure on education, total (% of GDP) | G1: Patent applications, residents | H1: Population, total | I1: Research and development expenditure (% of GDP) | J1: Trade (% of GDP) | K1: SDG INDEX
A2: Argentina | B2: ARG | C2: 2000 | D2: 22281.381 | E2: -0.028038694 | F2: 4.5803099 | G2: 1062 | H2: 37213984 | I2: 0.43884 | J2: 22.622445 | K2: 67.730349
A3: Argentina | B3: ARG | C3: 2001 | D3: 21066.458 | F3: 4.8337402 | G3: 691 | H3: 37624825 | I3: 0.42461 | J3: 21.852255 | K3: 67.260308
A4: Argentina | B4: ARG | C4: 2002 | D4: 18571.702 | E4: -0.22847907 | F4: 4.0173402 | G4: 718 | H4: 38029349 | I4: 0.38886 | J4: 41.752724 | K4: 67.008104
A5: Argentina | B5: ARG | C5: 2003 | D5: 20005.139 | E5: -0.034219984 | F5: 3.5350499 | G5: 792 | H5: 38424282 | I5: 0.41013 | J5: 40.644748 | K5: 68.162192
A6: Argentina | B6: ARG | C6: 2004 | D6: 21591.449 | E6: 0.015197393 | F6: 3.4865201 | G6: 786 | H6: 38815916 | I6: 0.40376 | J6: 40.692646 | K6: 68.719854
A7: Argentina | B7: ARG | C7: 2005 | D7: 23262.408 | E7: -0.097979061 | F7: 3.8600099 | G7: 1054 | H7: 39216789 | I7: 0.42074 | J7: 40.551271 | K7: 69.553695
A8: Argentina | B8: ARG | C8: 2006 | D8: 24877.249 | E8: -0.033916309 | F8: 4.1282101 | G8: 1020 | H8: 39622115 | I8: 0.45216 | J8: 40.43348 | K8: 69.770265
A9: Argentina | B9: ARG | C9: 2007 | D9: 26850.665 | E9: -0.012532503 | F9: 4.4626002 | G9: 937 | H9: 40016763 | I9: 0.46007 | J9: 40.945171 | K9: 69.827567
A10: Argentina | B10: ARG | C10: 2008 | D10: 27658.485 | E10: -0.12350935 | F10: 4.8444099 | G10: 801 | H10: 40424148 | I10: 0.47055 | J10: 40.402673 | K10: 70.265185
A11: Argentina | B11: ARG | C11: 2009 | D11: 25747.198 | E11: -0.29403204 | F11: 5.5310502 | G11: 640 | H11: 40854831 | I11: 0.58398 | J11: 34.057127 | K11: 70.998197
A12: Argentina | B12: ARG | C12: 2010 | D12: 28056.257 | E12: -0.11179195 | F12: 5.0197101 | G12: 552 | H12: 41288694 | I12: 0.56104 | J12: 34.971013 | K12: 71.295016
A13: Argentina | B13: ARG | C13: 2011 | D13: 29425.759 | E13: -0.072361067 | F13: 5.2906299 | G13: 688 | H13: 41730660 | I13: 0.56597 | J13: 35.206155 | K13: 71.764539
A14: Argentina | B14: ARG | C14: 2012 | D14: 28825.967 | E14: -0.20696701 | F14: 5.34583 | G14: 735 | H14: 42161721 | I14: 0.63491 | J14: 30.526542 | K14: 72.383414
A15: Argentina | B15: ARG | C15: 2013 | D15: 29227.66 | E15: -0.25423697 | F15: 5.4366102 | G15: 643 | H15: 42582455 | I15: 0.61849 | J15: 29.333929 | K15: 72.746863
... A24: Armenia | B24: ARM | C24: 2000 | D24: 4589.0083 | E24: -0.54641759 | F24: 2.7727301 | G24: 119 | H24: 3221100 | I24: 0.19106 | J24: 72.23333 | K24: 66.915976
A25: Armenia | B25: ARM | C25: 2001 | D25: 5044.1165 | F25: 2.46944 | G25: 140 | H25: 3211800 | I25: 0.27987 | J25: 69.864266 | K25: 67.066378
A26: Armenia | B26: ARM | C26: 2002 | D26: 5731.3535 | E26: -0.045769267 | F26: 2.13504 | G26: 200 | H26: 3199800 | I26: 0.25255 | J26: 73.984502 | K26: 67.686034
A27: Armenia | B27: ARM | C27: 2003 | D27: 6569.2602 | E27: -0.1972537 | F27: 2.14504 | G27: 151 | H27: 3182500 | I27: 0.32109 | J27: 80.051368 | K27: 68.358445
A28: Armenia | B28: ARM | C28: 2004 | D28: 7299.4 | E28: -0.11826345 | F28: 2.4867301 | H28: 3164900 | I28: 0.25659 | J28: 73.070634 | K28: 67.792943
A29: Armenia | B29: ARM | C29: 2005 | D29: 8362.9008 | E29: -0.14249781 | F29: 2.7120299 | G29: 206 | H29: 3146400 | I29: 0.25761 | J29: 70.139739 | K29: 68.583865
A30: Armenia | B30: ARM | C30: 2006 | D30: 9525.2315 | E30: -0.26150292 | F30: 2.71577 | G30: 192 | H30: 3127100 | I30: 0.24057 | J30: 61.030138 | K30: 70.208829
A31: Armenia | B31: ARM | C31: 2007 | D31: 10898.848 | E31: -0.38190657 | F31: 3.01894 | G31: 135 | H31: 3107400 | I31: 0.21107 | J31: 56.975047 | K31: 70.26059
A32: Armenia | B32: ARM | C32: 2008 | D32: 11727.482 | E32: -0.17795259 | F32: 3.17273 | G32: 226 | H32: 3087100 | I32: 0.22438 | J32: 54.542328 | K32: 70.45218
A33: Armenia | B33: ARM | C33: 2009 | D33: 10143.235 | E33: -0.026895642 | F33: 3.84079 | G33: 116 | H33: 3066000 | I33: 0.29093 | J33: 57.274236 | K33: 71.373591
A34: Armenia | B34: ARM | C34: 2010 | D34: 10438.564 | E34: -0.17152315 | F34: 3.2490001 | G34: 136 | H34: 3044800 | I34: 0.24139 | J34: 64.642976 | K34: 71.329503
A35: Armenia | B35: ARM | C35: 2011 | D35: 10990.177 | E35: -0.11502831 | F35: 3.1438501 | G35: 121 | H35: 3027900 | I35: 0.27014 | J35: 69.435574 | K35: 71.945787
A36: Armenia | B36: ARM | C36: 2012 | D36: 11796.274 | E36: -0.032386623 | F36: 2.77248 | G36: 137 | H36: 3024100 | I36: 0.23853 | J36: 75.961676 | K36: 71.732128
A37: Armenia | B37: ARM | C37: 2013 | D37: 12194.019 | E37: 0.078317285 | F37: 2.6501801 | G37: 125 | H37: 3022000 | I37: 0.22216 | J37: 77.555048 | K37: 71.784417
A38: Armenia | B38: ARM | C38: 2014 | D38: 12667.376 | E38: -0.25732976 | F38: 2.2472401 | G38: 121 | H38: 3013800 | I38: 0.24151 | J38: 75.778867 | K38: 71.642056
A39: Armenia | B39: ARM | C39: 2015 | D39: 13112.76 | E39: -0.33178961 | F39: 2.8059101 | G39: 113 | H39: 3004600 | I39: 0.25002 | J39: 71.682074 | K39: 71.841488
A40: Armenia | B40: ARM | C40: 2016 | D40: 13192.994 | E40: -0.31255442 | F40: 2.7581201 | G40: 125 | H40: 2992300 | I40: 0.23305 | J40: 76.077967 | K40: 71.886708
... A46: Austria | B46: AUT | C46: 2000 | D46: 53534.342 | E46: 1.8472652 | F46: 5.6203699 | G46: 1961 | H46: 8011566 | I46: 1.88602 | J46: 85.842608 | K46: 80.279803
A47: Austria | B47: AUT | C47: 2001 | D47: 54032.152 | F47: 5.6047502 | G47: 1815 | H47: 8042293 | I47: 1.9921 | J47: 87.996257 | K47: 80.628765
A48: Austria | B48: AUT | C48: 2002 | D48: 54565.077 | E48: 1.8802282 | F48: 5.5625501 | G48: 1932 | H48: 8081957 | I48: 2.06598 | J48: 87.584494 | K48: 80.588374
A49: Austria | B49: AUT | C49: 2003 | D49: 54919.787 | E49: 1.9304613 | F49: 5.39254 | G49: 2120 | H49: 8121423 | I49: 2.17456 | J49: 86.882226 | K49: 80.490877
A50: Austria | B50: AUT | C50: 2004 | D50: 55980.232 | E50: 1.8437706 | F50: 5.3422499 | G50: 2248 | H50: 8171966 | I50: 2.16612 | J50: 91.47422 | K50: 80.815833
A51: Austria | B51: AUT | C51: 2005 | D51: 56890.279 | E51: 1.6795291 | F51: 5.2851501 | G51: 2270 | H51: 8227829 | I51: 2.37324 | J51: 94.674755 | K51: 81.146732
A52: Austria | B52: AUT | C52: 2006 | D52: 58460.237 | E52: 1.8273852 | F52: 5.26368 | G52: 2271 | H52: 8268641 | I52: 2.35923 | J52: 98.785725 | K52: 81.066456
A53: Austria | B53: AUT | C53: 2007 | D53: 60470.91 | E53: 1.8635659 | F53: 5.1791801 | G53: 2385 | H53: 8295487 | I53: 2.41843 | J53: 101.36496 | K53: 81.182494
...

Sheet Pais_agregado_media
A1: País | B1: Código país | C1: n_years | D1: GDP per capita, PPP (constant 2021 international $) | E1: Government Effectiveness: Estimate | F1: Government expenditure on education, total (% of GDP) | G1: Patent applications, residents | H1: Population, total | I1: Research and development expenditure (% of GDP) | J1: Trade (% of GDP) | K1: SDG INDEX | L1: SDG INDEX 2021 | M1: SDG INDEX 2025 | N1: SDG INDEX 2025 - 2021 | O1: GDP per capita, PPP (constant 2021 international $) - valid observations | P1: Government Effectiveness: Estimate - valid observations | Q1: Government expenditure on education, total (% of GDP) - valid observations | R1: Patent applications, residents - valid observations | S1: Population, total - valid observations | T1: Research and development expenditure (% of GDP) - valid observations | U1: Trade (% of GDP) - valid observations | V1: SDG INDEX - valid observations
A2: Argentina | B2: ARG | C2: 22 | D2: 25664.947 | E2: -0.09652992 | F2: 4.8222546 | G2: 711.54545 | H2: 41492246 | I2: 0.50886364 | J2: 32.861101 | K2: 71.28636 | L2: 74.298191 | M2: 74.836351 | N2: 0.5381602 | O2: 22 | P2: 21 | Q2: 22 | R2: 22 | S2: 22 | T2: 22 | U2: 22 | V2: 22
A3: Armenia | B3: ARM | C3: 22 | D3: 10943.36 | E3: -0.2036037 | F3: 2.7068261 | G3: 132.66667 | H3: 3067195.5 | I3: 0.23783955 | J3: 73.054206 | K3: 70.749834 | L3: 73.909824 | M3: 74.253556 | N3: 0.34373232 | O3: 22 | P3: 21 | Q3: 22 | R3: 21 | S3: 22 | T3: 22 | U3: 22 | V3: 22
A4: Austria | B4: AUT | C4: 22 | D4: 59527.398 | E4: 1.6610722 | F4: 5.4654959 | G4: 2141.3636 | H4: 8448510.6 | I4: 2.6756473 | J4: 99.250267 | K4: 82.383105 | L4: 84.331371 | M4: 83.012913 | N4: -1.3184576 | O4: 22 | P4: 21 | Q4: 22 | R4: 22 | S4: 22 | T4: 22 | U4: 22 | V4: 22
A5: Azerbaijan | B5: AZE | C5: 22 | D5: 15918.567 | E5: -0.54360978 | F5: 2.9701986 | G5: 200.71429 | H5: 9089631 | I5: 0.23048909 | J5: 87.171217 | K5: 68.713133 | L5: 73.02804 | M5: 72.900156 | N5: -0.12788344 | O5: 22 | P5: 21 | Q5: 22 | R5: 21 | S5: 22 | T5: 22 | U5: 22 | V5: 22
A6: Bangladesh | B6: BGD | C6: 22 | D6: 4549.1433 | E6: -0.77035589 | F6: 1.9914083 | G6: 54.454545 | H6: 1.5244321e+08 | J6: 35.714604 | K6: 57.639984 | L6: 63.242469 | M6: 63.882219 | N6: 0.63974965 | O6: 22 | P6: 21 | Q6: 20 | R6: 22 | S6: 22 | T6: 0 | U6: 22 | V6: 22
A7: Belarus | B7: BLR | C7: 22 | D7: 21571.146 | E7: -0.86555928 | F7: 5.1046833 | G7: 1003.1818 | H7: 9562614.9 | I7: 0.63048273 | J7: 129.6651 | K7: 76.601243 | L7: 79.433715 | M7: 78.465707 | N7: -0.96800878 | O7: 22 | P7: 21 | Q7: 18 | R7: 22 | S7: 22 | T7: 22 | U7: 22 | V7: 22
A8: Belgium | B8: BEL | C8: 22 | D8: 55951.438 | E8: 1.5350406 | F8: 6.4245807 | G8: 706.13636 | H8: 10920794 | I8: 2.2985855 | J8: 153.04001 | K8: 77.073346 | L8: 80.370939 | M8: 80.673855 | N8: 0.30291623 | O8: 22 | P8: 21 | Q8: 15 | R8: 22 | S8: 22 | T8: 22 | U8: 22 | V8: 22
A9: Bosnia and Herzegovina | B9: BIH | C9: 22 | D9: 12471.907 | E9: -0.72730151 | F9: 3.566161 | G9: 48.5 | H9: 3770151.5 | I9: 0.14071824 | J9: 86.407945 | K9: 70.597984 | L9: 73.498815 | M9: 73.750695 | N9: 0.25188004 | O9: 22 | P9: 21 | Q9: 8 | R9: 18 | S9: 22 | T9: 17 | U9: 22 | V9: 22
A10: Brazil | B10: BRA | C10: 22 | D10: 16900.856 | E10: -0.20813114 | F10: 5.3237843 | G10: 4446.0909 | H10: 1.9364812e+08 | I10: 1.1234338 | J10: 26.755538 | K10: 70.417481 | L10: 72.727048 | M10: 73.812205 | N10: 1.0851575 | O10: 22 | P10: 21 | Q10: 21 | R10: 22 | S10: 22 | T10: 21 | U10: 22 | V10: 22
A11: Bulgaria | B11: BGR | C11: 22 | D11: 21747.997 | E11: -0.0053402344 | F11: 3.98218 | G11: 240.09091 | H11: 7300079.2 | I11: 0.60873091 | J11: 110.26357 | K11: 72.998467 | L11: 75.953734 | M11: 76.302653 | N11: 0.34891835 | O11: 22 | P11: 21 | Q11: 18 | R11: 22 | S11: 22 | T11: 22 | U11: 22 | V11: 22
A12: Canada | B12: CAN | C12: 22 | D12: 53517.999 | E12: 1.7740158 | F12: 4.9018705 | G12: 4547.0455 | H12: 34278218 | I12: 1.8461345 | J12: 66.870846 | K12: 77.374366 | L12: 79.037149 | M12: 79.168559 | N12: 0.1314098 | O12: 22 | P12: 21 | Q12: 18 | R12: 22 | S12: 22 | T12: 22 | U12: 22 | V12: 22
A13: Chile | B13: CHL | C13: 22 | D13: 24156.936 | E13: 1.0043362 | F13: 4.3925285 | G13: 372.04545 | H13: 17365044 | I13: 0.35813667 | J13: 65.475125 | K13: 74.600734 | L13: 77.805214 | M13: 78.051833 | N13: 0.24661868 | O13: 22 | P13: 21 | Q13: 20 | R13: 22 | S13: 22 | T13: 15 | U13: 22 | V13: 22
A14: China | B14: CHN | C14: 22 | D14: 11314.18 | E14: 0.19073177 | G14: 572197.64 | H14: 1343535000 | I14: 1.6959955 | J14: 45.821642 | K14: 66.825083 | L14: 73.985571 | M14: 74.392781 | N14: 0.40720986 | O14: 22 | P14: 21 | Q14: 0 | R14: 22 | S14: 22 | T14: 22 | U14: 22 | V14: 22
A15: Colombia | B15: COL | C15: 22 | D15: 14342.863 | E15: -0.131904 | F15: 4.3576857 | G15: 232.45455 | H15: 44974962 | I15: 0.22189048 | J15: 36.659809 | K15: 67.053079 | L15: 69.374692 | M15: 70.455097 | N15: 1.0804056 | O15: 22 | P15: 21 | Q15: 21 | R15: 22 | S15: 22 | T15: 21 | U15: 22 | V15: 22
A16: Costa Rica | B16: CRI | C16: 22 | D16: 18926.628 | E16: 0.2754361 | F16: 5.9494919 | G16: 17.681818 | H16: 4555764.3 | I16: 0.42789333 | J16: 73.732694 | K16: 70.049894 | L16: 72.995215 | M16: 73.44368 | N16: 0.44846545 | O16: 22 | P16: 21 | Q16: 21 | R16: 22 | S16: 22 | T16: 18 | U16: 22 | V16: 22
A17: Croatia | B17: HRV | C17: 22 | D17: 29140.493 | E17: 0.50258142 | F17: 4.0844614 | G17: 250.40909 | H17: 4205809.6 | I17: 0.89481 | J17: 84.832237 | K17: 77.336214 | L17: 82.443467 | M17: 82.389292 | N17: -0.054175444 | O17: 22 | P17: 21 | Q17: 14 | R17: 22 | S17: 22 | T17: 22 | U17: 22 | V17: 22
A18: Cyprus | B18: CYP | C18: 22 | D18: 40807.634 | E18: 1.1687423 | F18: 6.058397 | G18: 6.0588235 | H18: 1135801.5 | I18: 0.46393727 | J18: 127.87186 | K18: 70.558451 | L18: 73.599996 | M18: 73.75586 | N18: 0.15586334 | O18: 22 | P18: 21 | Q18: 20 | R18: 17 | S18: 22 | T18: 22 | U18: 22 | V18: 22
A19: Czechia | B19: CZE | C19: 22 | D19: 39205.727 | E19: 0.92869786 | F19: 4.2017668 | G19: 721.63636 | H19: 10425924 | I19: 1.51969 | J19: 128.20384 | K19: 79.478383 | L19: 82.556666 | M19: 81.93561 | N19: -0.62105612 | O19: 22 | P19: 21 | Q19: 22 | R19: 22 | S19: 22 | T19: 22 | U19: 22 | V19: 22
A20: Denmark | B20: DNK | C20: 22 | D20: 62170.871 | E20: 2.0102172 | F20: 7.8309867 | G20: 1532.5455 | H20: 5574781.2 | I20: 2.7466436 | J20: 97.763894 | K20: 82.961391 | L20: 84.913088 | M20: 85.256608 | N20: 0.34352063 | O20: 22 | P20: 21 | Q20: 21 | R20: 22 | S20: 22 | T20: 22 | U20: 22 | V20: 22
A21: Egypt, Arab Rep. | B21: EGY | C21: 22 | D21: 12582.548 | E21: -0.45048706 | F21: 4.3096666 | G21: 679.04762 | H21: 91250328 | I21: 0.52918947 | J21: 45.897181 | K21: 65.232358 | L21: 67.798087 | M21: 68.09105 | N21: 0.29296277 | O21: 22 | P21: 21 | Q21: 6 | R21: 21 | S21: 22 | T21: 19 | U21: 22 | V21: 22
A22: Estonia | B22: EST | C22: 22 | D22: 33177.367 | E22: 1.0264247 | F22: 5.1069814 | G22: 34.909091 | H22: 1340166 | I22: 1.320935 | J22: 141.53158 | K22: 76.596868 | L22: 80.337069 | M22: 80.760674 | N22: 0.4236044 | O22: 22 | P22: 21 | Q22: 21 | R22: 22 | S22: 22 | T22: 22 | U22: 22 | V22: 22
A23: Finland | B23: FIN | C23: 22 | D23: 53477.614 | E23: 2.0637061 | F23: 6.3940127 | G23: 1729.7727 | H23: 5368917 | I23: 3.2037373 | J23: 75.834781 | K23: 84.953574 | L23: 86.762526 | M23: 87.022462 | N23: 0.2599355 | O23: 22 | P23: 21 | Q23: 22 | R23: 22 | S23: 22 | T23: 22 | U23: 22 | V23: 22
A24: France | B24: FRA | C24: 22 | D24: 49568.039 | E24: 1.4675864 | F24: 5.466554 | G24: 14163.091 | H24: 64884713 | I24: 2.1663814 | J24: 59.561663 | K24: 79.767984 | L24: 82.994769 | M24: 83.139233 | N24: 0.14446475 | O24: 22 | P24: 21 | Q24: 5 | R24: 22 | S24: 22 | T24: 22 | U24: 22 | V24: 22
A25: Georgia | B25: GEO | C25: 22 | D25: 12095.977 | E25: 0.21463579 | F25: 2.8919397 | G25: 164.72727 | H25: 3819220.5 | I25: 0.231312 | J25: 88.324986 | K25: 69.38803 | L25: 73.368597 | M25: 73.672216 | N25: 0.30361899 | O25: 22 | P25: 21 | Q25: 22 | R25: 22 | S25: 22 | T25: 15 | U25: 22 | V25: 22
A26: Germany | B26: DEU | C26: 22 | D26: 56203.587 | E26: 1.5442636 | F26: 4.9178523 | G26: 47366.364 | H26: 82108129 | I26: 2.7492086 | J26: 72.005006 | K26: 80.509771 | L26: 83.24736 | M26: 83.6696 | N26: 0.42223955 | O26: 22 | P26: 21 | Q26: 13 | R26: 22 | S26: 22 | T26: 22 | U26: 22 | V26: 22
... A77: Zambia | B77: ZMB | C77: 22 | D77: 3080.5002 | E77: -0.77786747 | F77: 3.2931811 | G77: 9.9047619 | H77: 14397923 | I77: 0.067852 | J77: 69.492502 | K77: 49.528428 | L77: 53.595438 | M77: 54.772348 | N77: 1.1769093 | O77: 22 | P77: 21 | Q77: 17 | R77: 21 | S77: 22 | T77: 5 | U77: 22 | V77: 22

Sheet Transformaciones
A1: País | B1: Código país | C1: n_years | D1: GDP per capita, PPP (constant 2021 international $) | E1: Patent applications, residents | F1: Population, total | G1: Government Effectiveness: Estimate | H1: Government expenditure on education, total (% of GDP) | I1: Research and development expenditure (% of GDP) | J1: Trade (% of GDP) | K1: SDG INDEX | L1: SDG INDEX 2021 | M1: SDG INDEX 2025 | N1: SDG INDEX 2025 - 2021 | O1: Patents per million inhabitants | P1: ln_GDP_per_capita_PPP | Q1: ln_Patents_per_million_plus_1 | R1: Final ln GDP per capita PPP | S1: Final Government Effectiveness | T1: Final Education expenditure (% GDP) | U1: Final ln Patents per million + 1 | V1: Final Research expenditure (% GDP) | W1: Final Trade (% GDP)
A2: Argentina | B2: ARG | C2: 22 | D2: 25664.947 | E2: 711.54545 | F2: 41492246 | G2: -0.09652992 | H2: 4.8222546 | I2: 0.50886364 | J2: 32.861101 | K2: 71.28636 | L2: 74.298191 | M2: 74.836351 | N2: 0.5381602 | O2: 17.148878 | P2: 10.152881 | Q2: 2.8986087 | R2: 10.152881 | S2: -0.09652992 | T2: 4.8222546 | U2: 2.8986087 | V2: 0.50886364 | W2: 32.861101
A3: Armenia | B3: ARM | C3: 22 | D3: 10943.36 | E3: 132.66667 | F3: 3067195.5 | G3: -0.2036037 | H3: 2.7068261 | I3: 0.23783955 | J3: 73.054206 | K3: 70.749834 | L3: 73.909824 | M3: 74.253556 | N3: 0.34373232 | O3: 43.253411 | P3: 9.3004882 | Q3: 3.7899325 | R3: 9.3004882 | S3: -0.2036037 | T3: 2.7068261 | U3: 3.7899325 | V3: 0.23783955 | W3: 73.054206
A4: Austria | B4: AUT | C4: 22 | D4: 59527.398 | E4: 2141.3636 | F4: 8448510.6 | G4: 1.6610722 | H4: 5.4654959 | I4: 2.6756473 | J4: 99.250267 | K4: 82.383105 | L4: 84.331371 | M4: 83.012913 | N4: -1.3184576 | O4: 253.46049 | P4: 10.994192 | Q4: 5.5391456 | R4: 10.994192 | S4: 1.6610722 | T4: 5.4654959 | U4: 5.5391456 | V4: 2.6756473 | W4: 99.250267
A5: Azerbaijan | B5: AZE | C5: 22 | D5: 15918.567 | E5: 200.71429 | F5: 9089631 | G5: -0.54360978 | H5: 2.9701986 | I5: 0.23048909 | J5: 87.171217 | K5: 68.713133 | L5: 73.02804 | M5: 72.900156 | N5: -0.12788344 | O5: 22.081676 | P5: 9.6752414 | Q5: 3.1390391 | R5: 9.6752414 | S5: -0.54360978 | T5: 2.9701986 | U5: 3.1390391 | V5: 0.23048909 | W5: 87.171217
A6: Bangladesh | B6: BGD | C6: 22 | D6: 4549.1433 | E6: 54.454545 | F6: 1.5244321e+08 | G6: -0.77035589 | H6: 1.9914083 | J6: 35.714604 | K6: 57.639984 | L6: 63.242469 | M6: 63.882219 | N6: 0.63974965 | O6: 0.35721202 | P6: 8.4226942 | Q6: 0.30543261 | R6: 8.4226942 | S6: -0.77035589 | T6: 1.9914083 | U6: 0.30543261 | W6: 35.714604
A7: Belarus | B7: BLR | C7: 22 | D7: 21571.146 | E7: 1003.1818 | F7: 9562614.9 | G7: -0.86555928 | H7: 5.1046833 | I7: 0.63048273 | J7: 129.6651 | K7: 76.601243 | L7: 79.433715 | M7: 78.465707 | N7: -0.96800878 | O7: 104.90664 | P7: 9.9791119 | Q7: 4.662558 | R7: 9.9791119 | S7: -0.86555928 | T7: 5.1046833 | U7: 4.662558 | V7: 0.63048273 | W7: 129.6651
A8: Belgium | B8: BEL | C8: 22 | D8: 55951.438 | E8: 706.13636 | F8: 10920794 | G8: 1.5350406 | H8: 6.4245807 | I8: 2.2985855 | J8: 153.04001 | K8: 77.073346 | L8: 80.370939 | M8: 80.673855 | N8: 0.30291623 | O8: 64.6598 | P8: 10.932239 | Q8: 4.1844869 | R8: 10.932239 | S8: 1.5350406 | T8: 6.4245807 | U8: 4.1844869 | V8: 2.2985855 | W8: 153.04001
A9: Bosnia and Herzegovina | B9: BIH | C9: 22 | D9: 12471.907 | E9: 48.5 | F9: 3770151.5 | G9: -0.72730151 | H9: 3.566161 | I9: 0.14071824 | J9: 86.407945 | K9: 70.597984 | L9: 73.498815 | M9: 73.750695 | N9: 0.25188004 | O9: 12.864204 | P9: 9.431234 | Q9: 2.6293103 | R9: 9.431234 | S9: -0.72730151 | T9: 3.566161 | U9: 2.6293103 | V9: 0.14071824 | W9: 86.407945
A10: Brazil | B10: BRA | C10: 22 | D10: 16900.856 | E10: 4446.0909 | F10: 1.9364812e+08 | G10: -0.20813114 | H10: 5.3237843 | I10: 1.1234338 | J10: 26.755538 | K10: 70.417481 | L10: 72.727048 | M10: 73.812205 | N10: 1.0851575 | O10: 22.959638 | P10: 9.7351195 | Q10: 3.1763707 | R10: 9.7351195 | S10: -0.20813114 | T10: 5.3237843 | U10: 3.1763707 | V10: 1.1234338 | W10: 26.755538
A11: Bulgaria | B11: BGR | C11: 22 | D11: 21747.997 | E11: 240.09091 | F11: 7300079.2 | G11: -0.0053402344 | H11: 3.98218 | I11: 0.60873091 | J11: 110.26357 | K11: 72.998467 | L11: 75.953734 | M11: 76.302653 | N11: 0.34891835 | O11: 32.888809 | P11: 9.987277 | Q11: 3.5230848 | R11: 9.987277 | S11: -0.0053402344 | T11: 3.98218 | U11: 3.5230848 | V11: 0.60873091 | W11: 110.26357
A12: Canada | B12: CAN | C12: 22 | D12: 53517.999 | E12: 4547.0455 | F12: 34278218 | G12: 1.7740158 | H12: 4.9018705 | I12: 1.8461345 | J12: 66.870846 | K12: 77.374366 | L12: 79.037149 | M12: 79.168559 | N12: 0.1314098 | O12: 132.65116 | P12: 10.887773 | Q12: 4.8952331 | R12: 10.887773 | S12: 1.7740158 | T12: 4.9018705 | U12: 4.8952331 | V12: 1.8461345 | W12: 66.870846
A13: Chile | B13: CHL | C13: 22 | D13: 24156.936 | E13: 372.04545 | F13: 17365044 | G13: 1.0043362 | H13: 4.3925285 | I13: 0.35813667 | J13: 65.475125 | K13: 74.600734 | L13: 77.805214 | M13: 78.051833 | N13: 0.24661868 | O13: 21.424965 | P13: 10.092327 | Q13: 3.1101748 | R13: 10.092327 | S13: 1.0043362 | T13: 4.3925285 | U13: 3.1101748 | V13: 0.35813667 | W13: 65.475125
A14: China | B14: CHN | C14: 22 | D14: 11314.18 | E14: 572197.64 | F14: 1343535000 | G14: 0.19073177 | I14: 1.6959955 | J14: 45.821642 | K14: 66.825083 | L14: 73.985571 | M14: 74.392781 | N14: 0.40720986 | O14: 425.88964 | P14: 9.3338121 | Q14: 6.0565255 | R14: 9.3338121 | S14: 0.19073177 | U14: 6.0565255 | V14: 1.6959955 | W14: 45.821642
A15: Colombia | B15: COL | C15: 22 | D15: 14342.863 | E15: 232.45455 | F15: 44974962 | G15: -0.131904 | H15: 4.3576857 | I15: 0.22189048 | J15: 36.659809 | K15: 67.053079 | L15: 69.374692 | M15: 70.455097 | N15: 1.0804056 | O15: 5.1685323 | P15: 9.5710078 | Q15: 1.8194609 | R15: 9.5710078 | S15: -0.131904 | T15: 4.3576857 | U15: 1.8194609 | V15: 0.22189048 | W15: 36.659809
A16: Costa Rica | B16: CRI | C16: 22 | D16: 18926.628 | E16: 17.681818 | F16: 4555764.3 | G16: 0.2754361 | H16: 5.9494919 | I16: 0.42789333 | J16: 73.732694 | K16: 70.049894 | L16: 72.995215 | M16: 73.44368 | N16: 0.44846545 | O16: 3.8811969 | P16: 9.8483251 | Q16: 1.5853904 | R16: 9.8483251 | S16: 0.2754361 | T16: 5.9494919 | U16: 1.5853904 | V16: 0.42789333 | W16: 73.732694
A17: Croatia | B17: HRV | C17: 22 | D17: 29140.493 | E17: 250.40909 | F17: 4205809.6 | G17: 0.50258142 | H17: 4.0844614 | I17: 0.89481 | J17: 84.832237 | K17: 77.336214 | L17: 82.443467 | M17: 82.389292 | N17: -0.054175444 | O17: 59.538855 | P17: 10.279884 | Q17: 4.1032854 | R17: 10.279884 | S17: 0.50258142 | T17: 4.0844614 | U17: 4.1032854 | V17: 0.89481 | W17: 84.832237
A18: Cyprus | B18: CYP | C18: 22 | D18: 40807.634 | E18: 6.0588235 | F18: 1135801.5 | G18: 1.1687423 | H18: 6.058397 | I18: 0.46393727 | J18: 127.87186 | K18: 70.558451 | L18: 73.599996 | M18: 73.75586 | N18: 0.15586334 | O18: 5.3344033 | P18: 10.616624 | Q18: 1.8459956 | R18: 10.616624 | S18: 1.1687423 | T18: 6.058397 | U18: 1.8459956 | V18: 0.46393727 | W18: 127.87186
A19: Czechia | B19: CZE | C19: 22 | D19: 39205.727 | E19: 721.63636 | F19: 10425924 | G19: 0.92869786 | H19: 4.2017668 | I19: 1.51969 | J19: 128.20384 | K19: 79.478383 | L19: 82.556666 | M19: 81.93561 | N19: -0.62105612 | O19: 69.215578 | P19: 10.576578 | Q19: 4.2515702 | R19: 10.576578 | S19: 0.92869786 | T19: 4.2017668 | U19: 4.2515702 | V19: 1.51969 | W19: 128.20384
A20: Denmark | B20: DNK | C20: 22 | D20: 62170.871 | E20: 1532.5455 | F20: 5574781.2 | G20: 2.0102172 | H20: 7.8309867 | I20: 2.7466436 | J20: 97.763894 | K20: 82.961391 | L20: 84.913088 | M20: 85.256608 | N20: 0.34352063 | O20: 274.90683 | P20: 11.037642 | Q20: 5.6200632 | R20: 11.037642 | S20: 2.0102172 | T20: 7.8309867 | U20: 5.6200632 | V20: 2.7466436 | W20: 97.763894
A21: Egypt, Arab Rep. | B21: EGY | C21: 22 | D21: 12582.548 | E21: 679.04762 | F21: 91250328 | G21: -0.45048706 | H21: 4.3096666 | I21: 0.52918947 | J21: 45.897181 | K21: 65.232358 | L21: 67.798087 | M21: 68.09105 | N21: 0.29296277 | O21: 7.441591 | P21: 9.4400661 | Q21: 2.1331708 | R21: 9.4400661 | S21: -0.45048706 | T21: 4.3096666 | U21: 2.1331708 | V21: 0.52918947 | W21: 45.897181
A22: Estonia | B22: EST | C22: 22 | D22: 33177.367 | E22: 34.909091 | F22: 1340166 | G22: 1.0264247 | H22: 5.1069814 | I22: 1.320935 | J22: 141.53158 | K22: 76.596868 | L22: 80.337069 | M22: 80.760674 | N22: 0.4236044 | O22: 26.048333 | P22: 10.409623 | Q22: 3.2976254 | R22: 10.409623 | S22: 1.0264247 | T22: 5.1069814 | U22: 3.2976254 | V22: 1.320935 | W22: 141.53158
A23: Finland | B23: FIN | C23: 22 | D23: 53477.614 | E23: 1729.7727 | F23: 5368917 | G23: 2.0637061 | H23: 6.3940127 | I23: 3.2037373 | J23: 75.834781 | K23: 84.953574 | L23: 86.762526 | M23: 87.022462 | N23: 0.2599355 | O23: 322.18281 | P23: 10.887018 | Q23: 5.7782181 | R23: 10.887018 | S23: 2.0637061 | T23: 6.3940127 | U23: 5.7782181 | V23: 3.2037373 | W23: 75.834781
A24: France | B24: FRA | C24: 22 | D24: 49568.039 | E24: 14163.091 | F24: 64884713 | G24: 1.4675864 | H24: 5.466554 | I24: 2.1663814 | J24: 59.561663 | K24: 79.767984 | L24: 82.994769 | M24: 83.139233 | N24: 0.14446475 | O24: 218.28086 | P24: 10.811102 | Q24: 5.3903534 | R24: 10.811102 | S24: 1.4675864 | T24: 5.466554 | U24: 5.3903534 | V24: 2.1663814 | W24: 59.561663
A25: Georgia | B25: GEO | C25: 22 | D25: 12095.977 | E25: 164.72727 | F25: 3819220.5 | G25: 0.21463579 | H25: 2.8919397 | I25: 0.231312 | J25: 88.324986 | K25: 69.38803 | L25: 73.368597 | M25: 73.672216 | N25: 0.30361899 | O25: 43.131124 | P25: 9.4006282 | Q25: 3.7871653 | R25: 9.4006282 | S25: 0.21463579 | T25: 2.8919397 | U25: 3.7871653 | V25: 0.231312 | W25: 88.324986
A26: Germany | B26: DEU | C26: 22 | D26: 56203.587 | E26: 47366.364 | F26: 82108129 | G26: 1.5442636 | H26: 4.9178523 | I26: 2.7492086 | J26: 72.005006 | K26: 80.509771 | L26: 83.24736 | M26: 83.6696 | N26: 0.42223955 | O26: 576.87789 | P26: 10.936736 | Q26: 6.3593626 | R26: 10.936736 | S26: 1.5442636 | T26: 4.9178523 | U26: 6.3593626 | V26: 2.7492086 | W26: 72.005006
... A77: Zambia | B77: ZMB | C77: 22 | D77: 3080.5002 | E77: 9.9047619 | F77: 14397923 | G77: -0.77786747 | H77: 3.2931811 | I77: 0.067852 | J77: 69.492502 | K77: 49.528428 | L77: 53.595438 | M77: 54.772348 | N77: 1.1769093 | O77: 0.68792992 | P77: 8.0328473 | Q77: 0.52350288 | R77: 8.0328473 | S77: -0.77786747 | T77: 3.2931811 | U77: 0.52350288 | V77: 0.067852 | W77: 69.492502

Sheet Modelo_final_tipificado
A1: País | B1: Código país | C1: SDG INDEX | D1: SDG INDEX 2021 | E1: SDG INDEX 2025 | F1: SDG INDEX 2025 - 2021 | G1: z_ln_GDP_per_capita_PPP | H1: z_Government_Effectiveness | I1: z_Education_expenditure_pct_GDP | J1: z_ln_Patents_per_million_plus_1 | K1: z_Research_expenditure_pct_GDP | L1: z_Trade_pct_GDP
A2: Argentina | B2: ARG | C2: 71.28636 | D2: 74.298191 | E2: 74.836351 | F2: 0.5381602 | G2: 0.1695615 | H2: -0.59729524 | I2: 0.19848777 | J2: -0.45423349 | K2: -0.59636585 | L2: -1.0297315
A3: Armenia | B3: ARM | C3: 70.749834 | D3: 73.909824 | E3: 74.253556 | F3: 0.34373232 | G3: -0.77298977 | H3: -0.71308066 | I3: -1.5008494 | J3: 0.068569353 | K3: -0.86594163 | L3: -0.31015024
A4: Austria | B4: AUT | C4: 82.383105 | D4: 84.331371 | E4: 83.012913 | F4: -1.3184576 | G4: 1.0998578 | H4: 1.3033074 | I4: 0.71520767 | J4: 1.0945642 | K4: 1.5588388 | L4: 0.15884056
A5: Azerbaijan | B5: AZE | C5: 68.713133 | D5: 73.02804 | E5: 72.900156 | F5: -0.12788344 | G5: -0.35859869 | H5: -1.08075 | I5: -1.2892806 | J5: -0.31320991 | K5: -0.8732528 | L5: -0.057411932
A6: Bangladesh | B6: BGD | C6: 57.639984 | D6: 63.242469 | E6: 63.882219 | F6: 0.63974965 | G6: -1.7436284 | H6: -1.3259445 | I6: -2.0755491 | J6: -1.9752519 | L6: -0.97864499
A7: Belarus | B7: BLR | C7: 76.601243 | D7: 79.433715 | E7: 78.465707 | F7: -0.96800878 | G7: -0.022587757 | H7: -1.4288937 | I7: 0.42536455 | J7: 0.58040482 | K7: -0.47539667 | L7: 0.70336051
A8: Belgium | B8: BEL | C8: 77.073346 | D8: 80.370939 | E8: 80.673855 | F8: 0.30291623 | G8: 1.0313525 | H8: 1.1670217 | I8: 1.4856466 | J8: 0.29999387 | K8: 1.183792 | L8: 1.1218439
A9: Bosnia and Herzegovina | B9: BIH | C9: 70.597984 | D9: 73.498815 | E9: 73.750695 | F9: 0.25188004 | G9: -0.62841492 | H9: -1.2793871 | I9: -0.81054024 | J9: -0.61218955 | K9: -0.96254394 | L9: -0.071076858
A10: Brazil | B10: BRA | C10: 70.417481 | D10: 72.727048 | E10: 73.812205 | F10: 1.0851575 | G10: -0.29238724 | H10: -0.71797646 | I10: 0.60136982 | J10: -0.29131318 | K10: 0.014920161 | L10: -1.1390401
A11: Bulgaria | B11: BGR | C11: 72.998467 | D11: 75.953734 | E11: 76.302653 | F11: 0.34891835 | G11: -0.013559037 | H11: -0.49868625 | I11: -0.47634948 | J11: -0.087949196 | K11: -0.49703225 | L11: 0.35601291
A12: Canada | B12: CAN | C12: 77.374366 | D12: 79.037149 | E12: 79.168559 | F12: 0.1314098 | G12: 0.98218321 | H12: 1.4254402 | I12: 0.26244379 | J12: 0.71687962 | K12: 0.7337589 | L12: -0.42085157
A13: Chile | B13: CHL | C13: 74.600734 | D13: 77.805214 | E13: 78.051833 | F13: 0.24661868 | G13: 0.102602 | H13: 0.59313861 | I13: -0.14671396 | J13: -0.33014011 | K13: -0.74628735 | L13: -0.4458393
A14: China | B14: CHN | C14: 66.825083 | D14: 73.985571 | E14: 74.392781 | F14: 0.40720986 | G14: -0.73614121 | H14: -0.28666161 | J14: 1.3980316 | K14: 0.58442213 | L14: -0.79769764
A15: Colombia | B15: COL | C15: 67.053079 | D15: 69.374692 | E15: 70.455097 | F15: 1.0804056 | G15: -0.4738572 | H15: -0.6355474 | I15: -0.17470337 | J15: -1.0872039 | K15: -0.88180547 | L15: -0.96172289
A16: Costa Rica | B16: CRI | C16: 70.049894 | D16: 72.995215 | E16: 73.44368 | F16: 0.44846545 | G16: -0.1672079 | H16: -0.19506564 | I16: 1.1040047 | J16: -1.2244971 | K16: -0.67690346 | L16: -0.29800318
A17: Croatia | B17: HRV | C17: 77.336214 | D17: 82.443467 | E17: 82.389292 | F17: -0.054175444 | G17: 0.30999718 | H17: 0.050560491 | I17: -0.39418617 | J17: 0.25236543 | K17: -0.21248192 | L17: -0.099286928
A18: Cyprus | B18: CYP | C18: 70.558451 | D18: 73.599996 | E18: 73.75586 | F18: 0.15586334 | G18: 0.68235483 | H18: 0.77092098 | I18: 1.1914889 | J18: -1.07164 | K18: -0.64105213 | L18: 0.67125596
A19: Czechia | B19: CZE | C19: 79.478383 | D19: 82.556666 | E19: 81.93561 | F19: -0.62105612 | G19: 0.63807277 | H19: 0.51134625 | I19: -0.29995401 | J19: 0.33934136 | K19: 0.40905882 | L19: 0.67719938
A20: Denmark | B20: DNK | C20: 82.961391 | D20: 84.913088 | E20: 85.256608 | F20: 0.34352063 | G20: 1.1479034 | H20: 1.6808592 | I20: 2.6154215 | J20: 1.1420262 | K20: 1.6294558 | L20: 0.13222987
A21: Egypt, Arab Rep. | B21: EGY | C21: 65.232358 | D21: 67.798087 | E21: 68.09105 | F21: 0.29296277 | G21: -0.61864865 | H21: -0.98005073 | I21: -0.21327739 | J21: -0.90319844 | K21: -0.57614863 | L21: -0.79634527
A22: Estonia | B22: EST | C22: 76.596868 | D22: 80.337069 | E22: 80.760674 | F22: 0.4236044 | G22: 0.45345897 | H22: 0.61702425 | I22: 0.42721068 | J22: -0.22019165 | K22: 0.21136594 | L22: 0.91580729
A23: Finland | B23: FIN | C23: 84.953574 | D23: 86.762526 | E23: 87.022462 | F23: 0.2599355 | G23: 0.98134848 | H23: 1.7387001 | I23: 1.4610911 | J23: 1.2347914 | K23: 2.0841068 | L23: -0.26036931
A24: France | B24: FRA | C24: 79.767984 | D24: 82.994769 | E24: 83.139233 | F24: 0.14446475 | G24: 0.89740183 | H24: 1.0940793 | I24: 0.7160576 | J24: 1.0072907 | K24: 1.0522944 | L24: -0.55170863
A25: Georgia | B25: GEO | C25: 69.38803 | D25: 73.368597 | E25: 73.672216 | F25: 0.30361899 | G25: -0.66225791 | H25: -0.26081273 | I25: -1.3521465 | J25: 0.066946286 | K25: -0.87243429 | L25: -0.036755882
A26: Germany | B26: DEU | C26: 80.509771 | D26: 83.24736 | E26: 83.6696 | F26: 0.42223955 | G26: 1.0363246 | H26: 1.1769951 | I26: 0.27528203 | J26: 1.5756597 | K26: 1.6320071 | L26: -0.32893417
... A77: Zambia | B77: ZMB | C77: 49.528428 | D77: 53.595438 | E77: 54.772348 | F77: 1.1769093 | G77: -2.1747096 | H77: -1.3340672 | I77: -1.0298267 | J77: -1.8473436 | K77: -1.0350208 | L77: -0.37391579

Sheet Analisis_descriptivo
A1: Análisis descriptivo - Modelo final tipificado
A3: Indicador | B3: Valor | M3: Lectura rápida | N3: Resultado
A4: Países analizados | B4: =COUNTA(Modelo_final_tipificado!A2:A77) -> 76 | M4: Mayor nivel 2025 | N4: =B8&" ("&ROUND(MAX(Modelo_final_tipificado!E2:E77),3)&")" -> Finland (87,022)
A5: Variables numéricas | B5: 10 | M5: Menor nivel 2025 | N5: =INDEX(Modelo_final_tipificado!A2:A77,MATCH(MIN(Modelo_final_tipificado!E2:E77),Modelo_final_tipificado!E2:E77,0))&" ("&ROUND(MIN(Modelo_final_tipificado!E2:E77),3)&")" -> Madagascar (51,049)
A6: Celdas numéricas faltantes | B6: =COUNTBLANK(Modelo_final_tipificado!C2:L77) -> 2 | M6: Mayor mejora | N6: =B9&" ("&ROUND(MAX(Modelo_final_tipificado!F2:F77),3)&")" -> Singapore (2,741)
A7: Media SDG INDEX 2025 | B7: =AVERAGE(Modelo_final_tipificado!E2:E77) -> 75.073933 | M7: Mayor deterioro | N7: =INDEX(Modelo_final_tipificado!A2:A77,MATCH(MIN(Modelo_final_tipificado!F2:F77),Modelo_final_tipificado!F2:F77,0))&" ("&ROUND(MIN(Modelo_final_tipificado!F2:F77),3)&")" -> Hungary (-1,412)
A8: País con mayor SDG INDEX 2025 | B8: =INDEX(Modelo_final_tipificado!A2:A77,MATCH(MAX(Modelo_final_tipificado!E2:E77),Modelo_final_tipificado!E2:E77,0)) -> Finland | M8: Nota | N8: Las variables z están tipificadas: media ≈ 0 y desv. est. ≈ 1.
A9: País con mayor mejora 2025-2021 | B9: =INDEX(Modelo_final_tipificado!A2:A77,MATCH(MAX(Modelo_final_tipificado!F2:F77),Modelo_final_tipificado!F2:F77,0)) -> Singapore
A11: Variable | B11: N | C11: Faltantes | D11: Media | E11: Mediana | F11: Desv. Est. | G11: Mín. | H11: Q1 | I11: Q3 | J11: Máx.
A12: SDG INDEX | B12: =COUNT(Modelo_final_tipificado!C2:C77) -> 76 | C12: =COUNTBLANK(Modelo_final_tipificado!C2:C77) -> 0 | D12: =AVERAGE(Modelo_final_tipificado!C2:C77) -> 71.352273 | E12: =MEDIAN(Modelo_final_tipificado!C2:C77) -> 73.009593 | F12: =_xlfn.STDEV.S(Modelo_final_tipificado!C2:C77) -> 7.9569011 | G12: =MIN(Modelo_final_tipificado!C2:C77) -> 48.080864 | H12: =_xlfn.QUARTILE.INC(Modelo_final_tipificado!C2:C77,1) -> 66.713381 | I12: =_xlfn.QUARTILE.INC(Modelo_final_tipificado!C2:C77,3) -> 77.379025 | J12: =MAX(Modelo_final_tipificado!C2:C77) -> 85.203854
A13: SDG INDEX 2021 | B13: =COUNT(Modelo_final_tipificado!D2:D77) -> 76 | C13: =COUNTBLANK(Modelo_final_tipificado!D2:D77) -> 0 | D13: =AVERAGE(Modelo_final_tipificado!D2:D77) -> 74.70974 | E13: =MEDIAN(Modelo_final_tipificado!D2:D77) -> 75.565779 | F13: =_xlfn.STDEV.S(Modelo_final_tipificado!D2:D77) -> 7.3460839 | G13: =MIN(Modelo_final_tipificado!D2:D77) -> 51.212911 | H13: =_xlfn.QUARTILE.INC(Modelo_final_tipificado!D2:D77,1) -> 70.907911 | I13: =_xlfn.QUARTILE.INC(Modelo_final_tipificado!D2:D77,3) -> 80.307471 | J13: =MAX(Modelo_final_tipificado!D2:D77) -> 86.762526
A14: SDG INDEX 2025 | B14: =COUNT(Modelo_final_tipificado!E2:E77) -> 76 | C14: =COUNTBLANK(Modelo_final_tipificado!E2:E77) -> 0 | D14: =AVERAGE(Modelo_final_tipificado!E2:E77) -> 75.073933 | E14: =MEDIAN(Modelo_final_tipificado!E2:E77) -> 76.02351 | F14: =_xlfn.STDEV.S(Modelo_final_tipificado!E2:E77) -> 7.1530069 | G14: =MIN(Modelo_final_tipificado!E2:E77) -> 51.048878 | H14: =_xlfn.QUARTILE.INC(Modelo_final_tipificado!E2:E77,1) -> 71.537174 | I14: =_xlfn.QUARTILE.INC(Modelo_final_tipificado!E2:E77,3) -> 80.645982 | J14: =MAX(Modelo_final_tipificado!E2:E77) -> 87.022462
A15: SDG INDEX 2025 - 2021 | B15: =COUNT(Modelo_final_tipificado!F2:F77) -> 76 | C15: =COUNTBLANK(Modelo_final_tipificado!F2:F77) -> 0 | D15: =AVERAGE(Modelo_final_tipificado!F2:F77) -> 0.36419317 | E15: =MEDIAN(Modelo_final_tipificado!F2:F77) -> 0.34362647 | F15: =_xlfn.STDEV.S(Modelo_final_tipificado!F2:F77) -> 0.64127275 | G15: =MIN(Modelo_final_tipificado!F2:F77) -> -1.4115732 | H15: =_xlfn.QUARTILE.INC(Modelo_final_tipificado!F2:F77,1) -> 0.10922523 | I15: =_xlfn.QUARTILE.INC(Modelo_final_tipificado!F2:F77,3) -> 0.62513364 | J15: =MAX(Modelo_final_tipificado!F2:F77) -> 2.7411904
A16: z_ln_GDP_per_capita_PPP | B16: =COUNT(Modelo_final_tipificado!G2:G77) -> 76 | C16: =COUNTBLANK(Modelo_final_tipificado!G2:G77) -> 0 | D16: =AVERAGE(Modelo_final_tipificado!G2:G77) -> 6.135443e-16 | E16: =MEDIAN(Modelo_final_tipificado!G2:G77) -> 0.1700783 | F16: =_xlfn.STDEV.S(Modelo_final_tipificado!G2:G77) -> 1.0066446 | G16: =MIN(Modelo_final_tipificado!G2:G77) -> -2.8671947 | H16: =_xlfn.QUARTILE.INC(Modelo_final_tipificado!G2:G77,1) -> -0.63687567 | I16: =_xlfn.QUARTILE.INC(Modelo_final_tipificado!G2:G77,3) -> 0.71784503 | J16: =MAX(Modelo_final_tipificado!G2:G77) -> 1.9516583
A17: z_Government_Effectiveness | B17: =COUNT(Modelo_final_tipificado!H2:H77) -> 76 | C17: =COUNTBLANK(Modelo_final_tipificado!H2:H77) -> 0 | D17: =AVERAGE(Modelo_final_tipificado!H2:H77) -> 2.6294756e-17 | E17: =MEDIAN(Modelo_final_tipificado!H2:H77) -> -0.094126969 | F17: =_xlfn.STDEV.S(Modelo_final_tipificado!H2:H77) -> 1.0066446 | G17: =MIN(Modelo_final_tipificado!H2:H77) -> -1.6072726 | H17: =_xlfn.QUARTILE.INC(Modelo_final_tipificado!H2:H77,1) -> -0.91199634 | I17: =_xlfn.QUARTILE.INC(Modelo_final_tipificado!H2:H77,3) -> 0.78709042 | J17: =MAX(Modelo_final_tipificado!H2:H77) -> 1.8750224
A18: z_Education_expenditure_pct_GDP | B18: =COUNT(Modelo_final_tipificado!I2:I77) -> 75 | C18: =COUNTBLANK(Modelo_final_tipificado!I2:I77) -> 1 | D18: =AVERAGE(Modelo_final_tipificado!I2:I77) -> 8.8817842e-17 | E18: =MEDIAN(Modelo_final_tipificado!I2:I77) -> -0.003981204 | F18: =_xlfn.STDEV.S(Modelo_final_tipificado!I2:I77) -> 1.0067341 | G18: =MIN(Modelo_final_tipificado!I2:I77) -> -2.0755491 | H18: =_xlfn.QUARTILE.INC(Modelo_final_tipificado!I2:I77,1) -> -0.73979434 | I18: =_xlfn.QUARTILE.INC(Modelo_final_tipificado!I2:I77,3) -> 0.60070058 | J18: =MAX(Modelo_final_tipificado!I2:I77) -> 2.6154215
A19: z_ln_Patents_per_million_plus_1 | B19: =COUNT(Modelo_final_tipificado!J2:J77) -> 76 | C19: =COUNTBLANK(Modelo_final_tipificado!J2:J77) -> 0 | D19: =AVERAGE(Modelo_final_tipificado!J2:J77) -> -7.3040988e-17 | E19: =MEDIAN(Modelo_final_tipificado!J2:J77) -> 0.06775782 | F19: =_xlfn.STDEV.S(Modelo_final_tipificado!J2:J77) -> 1.0066446 | G19: =MIN(Modelo_final_tipificado!J2:J77) -> -2.0077321 | H19: =_xlfn.QUARTILE.INC(Modelo_final_tipificado!J2:J77,1) -> -0.6501479 | I19: =_xlfn.QUARTILE.INC(Modelo_final_tipificado!J2:J77,3) -> 0.79355574 | J19: =MAX(Modelo_final_tipificado!J2:J77) -> 2.4862187
A20: z_Research_expenditure_pct_GDP | B20: =COUNT(Modelo_final_tipificado!K2:K77) -> 75 | C20: =COUNTBLANK(Modelo_final_tipificado!K2:K77) -> 1 | D20: =AVERAGE(Modelo_final_tipificado!K2:K77) -> -1.4802974e-16 | E20: =MEDIAN(Modelo_final_tipificado!K2:K77) -> -0.4012224 | F20: =_xlfn.STDEV.S(Modelo_final_tipificado!K2:K77) -> 1.0067341 | G20: =MIN(Modelo_final_tipificado!K2:K77) -> -1.060008 | H20: =_xlfn.QUARTILE.INC(Modelo_final_tipificado!K2:K77,1) -> -0.7527151 | I20: =_xlfn.QUARTILE.INC(Modelo_final_tipificado!K2:K77,3) -> 0.61021085 | J20: =MAX(Modelo_final_tipificado!K2:K77) -> 3.2199065
A21: z_Trade_pct_GDP | B21: =COUNT(Modelo_final_tipificado!L2:L77) -> 76 | C21: =COUNTBLANK(Modelo_final_tipificado!L2:L77) -> 0 | D21: =AVERAGE(Modelo_final_tipificado!L2:L77) -> 1.3074337e-16 | E21: =MEDIAN(Modelo_final_tipificado!L2:L77) -> -0.26790374 | F21: =_xlfn.STDEV.S(Modelo_final_tipificado!L2:L77) -> 1.0066446 | G21: =MIN(Modelo_final_tipificado!L2:L77) -> -1.140147 | H21: =_xlfn.QUARTILE.INC(Modelo_final_tipificado!L2:L77,1) -> -0.60480331 | I21: =_xlfn.QUARTILE.INC(Modelo_final_tipificado!L2:L77,3) -> 0.36407666 | J21: =MAX(Modelo_final_tipificado!L2:L77) -> 4.8796012
A24: Top 10 SDG INDEX 2025 | B24: Código | C24: Valor | E24: Bottom 10 SDG INDEX 2025 | F24: Código | G24: Valor | I24: Top 10 mejora 2025-2021 | J24: Código | K24: Mejora
A25: =INDEX(Modelo_final_tipificado!$A$2:$A$77,MATCH(LARGE(Modelo_final_tipificado!$E$2:$E$77,1),Modelo_final_tipificado!$E$2:$E$77,0)) -> Finland | B25: =INDEX(Modelo_final_tipificado!$B$2:$B$77,MATCH(LARGE(Modelo_final_tipificado!$E$2:$E$77,1),Modelo_final_tipificado!$E$2:$E$77,0)) -> FIN | C25: =LARGE(Modelo_final_tipificado!$E$2:$E$77,1) -> 87.022462 | E25: =INDEX(Modelo_final_tipificado!$A$2:$A$77,MATCH(SMALL(Modelo_final_tipificado!$E$2:$E$77,1),Modelo_final_tipificado!$E$2:$E$77,0)) -> Madagascar | F25: =INDEX(Modelo_final_tipificado!$B$2:$B$77,MATCH(SMALL(Modelo_final_tipificado!$E$2:$E$77,1),Modelo_final_tipificado!$E$2:$E$77,0)) -> MDG | G25: =SMALL(Modelo_final_tipificado!$E$2:$E$77,1) -> 51.048878 | I25: =INDEX(Modelo_final_tipificado!$A$2:$A$77,MATCH(LARGE(Modelo_final_tipificado!$F$2:$F$77,1),Modelo_final_tipificado!$F$2:$F$77,0)) -> Singapore | J25: =INDEX(Modelo_final_tipificado!$B$2:$B$77,MATCH(LARGE(Modelo_final_tipificado!$F$2:$F$77,1),Modelo_final_tipificado!$F$2:$F$77,0)) -> SGP | K25: =LARGE(Modelo_final_tipificado!$F$2:$F$77,1) -> 2.7411904
A26: =INDEX(Modelo_final_tipificado!$A$2:$A$77,MATCH(LARGE(Modelo_final_tipificado!$E$2:$E$77,2),Modelo_final_tipificado!$E$2:$E$77,0)) -> Sweden | B26: =INDEX(Modelo_final_tipificado!$B$2:$B$77,MATCH(LARGE(Modelo_final_tipificado!$E$2:$E$77,2),Modelo_final_tipificado!$E$2:$E$77,0)) -> SWE | C26: =LARGE(Modelo_final_tipificado!$E$2:$E$77,2) -> 85.74133 | E26: =INDEX(Modelo_final_tipificado!$A$2:$A$77,MATCH(SMALL(Modelo_final_tipificado!$E$2:$E$77,2),Modelo_final_tipificado!$E$2:$E$77,0)) -> Zambia | F26: =INDEX(Modelo_final_tipificado!$B$2:$B$77,MATCH(SMALL(Modelo_final_tipificado!$E$2:$E$77,2),Modelo_final_tipificado!$E$2:$E$77,0)) -> ZMB | G26: =SMALL(Modelo_final_tipificado!$E$2:$E$77,2) -> 54.772348 | I26: =INDEX(Modelo_final_tipificado!$A$2:$A$77,MATCH(LARGE(Modelo_final_tipificado!$F$2:$F$77,2),Modelo_final_tipificado!$F$2:$F$77,0)) -> Philippines | J26: =INDEX(Modelo_final_tipificado!$B$2:$B$77,MATCH(LARGE(Modelo_final_tipificado!$F$2:$F$77,2),Modelo_final_tipificado!$F$2:$F$77,0)) -> PHL | K26: =LARGE(Modelo_final_tipificado!$F$2:$F$77,2) -> 1.6090772
A27: =INDEX(Modelo_final_tipificado!$A$2:$A$77,MATCH(LARGE(Modelo_final_tipificado!$E$2:$E$77,3),Modelo_final_tipificado!$E$2:$E$77,0)) -> Denmark | B27: =INDEX(Modelo_final_tipificado!$B$2:$B$77,MATCH(LARGE(Modelo_final_tipificado!$E$2:$E$77,3),Modelo_final_tipificado!$E$2:$E$77,0)) -> DNK | C27: =LARGE(Modelo_final_tipificado!$E$2:$E$77,3) -> 85.256608 | E27: =INDEX(Modelo_final_tipificado!$A$2:$A$77,MATCH(SMALL(Modelo_final_tipificado!$E$2:$E$77,3),Modelo_final_tipificado!$E$2:$E$77,0)) -> Pakistan | F27: =INDEX(Modelo_final_tipificado!$B$2:$B$77,MATCH(SMALL(Modelo_final_tipificado!$E$2:$E$77,3),Modelo_final_tipificado!$E$2:$E$77,0)) -> PAK | G27: =SMALL(Modelo_final_tipificado!$E$2:$E$77,3) -> 56.966133 | I27: =INDEX(Modelo_final_tipificado!$A$2:$A$77,MATCH(LARGE(Modelo_final_tipificado!$F$2:$F$77,3),Modelo_final_tipificado!$F$2:$F$77,0)) -> Malta | J27: =INDEX(Modelo_final_tipificado!$B$2:$B$77,MATCH(LARGE(Modelo_final_tipificado!$F$2:$F$77,3),Modelo_final_tipificado!$F$2:$F$77,0)) -> MLT | K27: =LARGE(Modelo_final_tipificado!$F$2:$F$77,3) -> 1.3522271
A28: =INDEX(Modelo_final_tipificado!$A$2:$A$77,MATCH(LARGE(Modelo_final_tipificado!$E$2:$E$77,4),Modelo_final_tipificado!$E$2:$E$77,0)) -> Germany | B28: =INDEX(Modelo_final_tipificado!$B$2:$B$77,MATCH(LARGE(Modelo_final_tipificado!$E$2:$E$77,4),Modelo_final_tipificado!$E$2:$E$77,0)) -> DEU | C28: =LARGE(Modelo_final_tipificado!$E$2:$E$77,4) -> 83.6696 | E28: =INDEX(Modelo_final_tipificado!$A$2:$A$77,MATCH(SMALL(Modelo_final_tipificado!$E$2:$E$77,4),Modelo_final_tipificado!$E$2:$E$77,0)) -> Guatemala | F28: =INDEX(Modelo_final_tipificado!$B$2:$B$77,MATCH(SMALL(Modelo_final_tipificado!$E$2:$E$77,4),Modelo_final_tipificado!$E$2:$E$77,0)) -> GTM | G28: =SMALL(Modelo_final_tipificado!$E$2:$E$77,4) -> 59.863792 | I28: =INDEX(Modelo_final_tipificado!$A$2:$A$77,MATCH(LARGE(Modelo_final_tipificado!$F$2:$F$77,4),Modelo_final_tipificado!$F$2:$F$77,0)) -> Mexico | J28: =INDEX(Modelo_final_tipificado!$B$2:$B$77,MATCH(LARGE(Modelo_final_tipificado!$F$2:$F$77,4),Modelo_final_tipificado!$F$2:$F$77,0)) -> MEX | K28: =LARGE(Modelo_final_tipificado!$F$2:$F$77,4) -> 1.2985237
A29: =INDEX(Modelo_final_tipificado!$A$2:$A$77,MATCH(LARGE(Modelo_final_tipificado!$E$2:$E$77,5),Modelo_final_tipificado!$E$2:$E$77,0)) -> France | B29: =INDEX(Modelo_final_tipificado!$B$2:$B$77,MATCH(LARGE(Modelo_final_tipificado!$E$2:$E$77,5),Modelo_final_tipificado!$E$2:$E$77,0)) -> FRA | C29: =LARGE(Modelo_final_tipificado!$E$2:$E$77,5) -> 83.139233 | E29: =INDEX(Modelo_final_tipificado!$A$2:$A$77,MATCH(SMALL(Modelo_final_tipificado!$E$2:$E$77,5),Modelo_final_tipificado!$E$2:$E$77,0)) -> Kenya | F29: =INDEX(Modelo_final_tipificado!$B$2:$B$77,MATCH(SMALL(Modelo_final_tipificado!$E$2:$E$77,5),Modelo_final_tipificado!$E$2:$E$77,0)) -> KEN | G29: =SMALL(Modelo_final_tipificado!$E$2:$E$77,5) -> 61.928932 | I29: =INDEX(Modelo_final_tipificado!$A$2:$A$77,MATCH(LARGE(Modelo_final_tipificado!$F$2:$F$77,5),Modelo_final_tipificado!$F$2:$F$77,0)) -> India | J29: =INDEX(Modelo_final_tipificado!$B$2:$B$77,MATCH(LARGE(Modelo_final_tipificado!$F$2:$F$77,5),Modelo_final_tipificado!$F$2:$F$77,0)) -> IND | K29: =LARGE(Modelo_final_tipificado!$F$2:$F$77,5) -> 1.2851896
A30: =INDEX(Modelo_final_tipificado!$A$2:$A$77,MATCH(LARGE(Modelo_final_tipificado!$E$2:$E$77,6),Modelo_final_tipificado!$E$2:$E$77,0)) -> Austria | B30: =INDEX(Modelo_final_tipificado!$B$2:$B$77,MATCH(LARGE(Modelo_final_tipificado!$E$2:$E$77,6),Modelo_final_tipificado!$E$2:$E$77,0)) -> AUT | C30: =LARGE(Modelo_final_tipificado!$E$2:$E$77,6) -> 83.012913 | E30: =INDEX(Modelo_final_tipificado!$A$2:$A$77,MATCH(SMALL(Modelo_final_tipificado!$E$2:$E$77,6),Modelo_final_tipificado!$E$2:$E$77,0)) -> Bangladesh | F30: =INDEX(Modelo_final_tipificado!$B$2:$B$77,MATCH(SMALL(Modelo_final_tipificado!$E$2:$E$77,6),Modelo_final_tipificado!$E$2:$E$77,0)) -> BGD | G30: =SMALL(Modelo_final_tipificado!$E$2:$E$77,6) -> 63.882219 | I30: =INDEX(Modelo_final_tipificado!$A$2:$A$77,MATCH(LARGE(Modelo_final_tipificado!$F$2:$F$77,6),Modelo_final_tipificado!$F$2:$F$77,0)) -> Malaysia | J30: =INDEX(Modelo_final_tipificado!$B$2:$B$77,MATCH(LARGE(Modelo_final_tipificado!$F$2:$F$77,6),Modelo_final_tipificado!$F$2:$F$77,0)) -> MYS | K30: =LARGE(Modelo_final_tipificado!$F$2:$F$77,6) -> 1.2536803
A31: =INDEX(Modelo_final_tipificado!$A$2:$A$77,MATCH(LARGE(Modelo_final_tipificado!$E$2:$E$77,7),Modelo_final_tipificado!$E$2:$E$77,0)) -> Norway | B31: =INDEX(Modelo_final_tipificado!$B$2:$B$77,MATCH(LARGE(Modelo_final_tipificado!$E$2:$E$77,7),Modelo_final_tipificado!$E$2:$E$77,0)) -> NOR | C31: =LARGE(Modelo_final_tipificado!$E$2:$E$77,7) -> 82.720585 | E31: =INDEX(Modelo_final_tipificado!$A$2:$A$77,MATCH(SMALL(Modelo_final_tipificado!$E$2:$E$77,7),Modelo_final_tipificado!$E$2:$E$77,0)) -> South Africa | F31: =INDEX(Modelo_final_tipificado!$B$2:$B$77,MATCH(SMALL(Modelo_final_tipificado!$E$2:$E$77,7),Modelo_final_tipificado!$E$2:$E$77,0)) -> ZAF | G31: =SMALL(Modelo_final_tipificado!$E$2:$E$77,7) -> 64.114309 | I31: =INDEX(Modelo_final_tipificado!$A$2:$A$77,MATCH(LARGE(Modelo_final_tipificado!$F$2:$F$77,7),Modelo_final_tipificado!$F$2:$F$77,0)) -> Zambia | J31: =INDEX(Modelo_final_tipificado!$B$2:$B$77,MATCH(LARGE(Modelo_final_tipificado!$F$2:$F$77,7),Modelo_final_tipificado!$F$2:$F$77,0)) -> ZMB | K31: =LARGE(Modelo_final_tipificado!$F$2:$F$77,7) -> 1.1769093
A32: =INDEX(Modelo_final_tipificado!$A$2:$A$77,MATCH(LARGE(Modelo_final_tipificado!$E$2:$E$77,8),Modelo_final_tipificado!$E$2:$E$77,0)) -> Croatia | B32: =INDEX(Modelo_final_tipificado!$B$2:$B$77,MATCH(LARGE(Modelo_final_tipificado!$E$2:$E$77,8),Modelo_final_tipificado!$E$2:$E$77,0)) -> HRV | C32: =LARGE(Modelo_final_tipificado!$E$2:$E$77,8) -> 82.389292 | E32: =INDEX(Modelo_final_tipificado!$A$2:$A$77,MATCH(SMALL(Modelo_final_tipificado!$E$2:$E$77,8),Modelo_final_tipificado!$E$2:$E$77,0)) -> Mongolia | F32: =INDEX(Modelo_final_tipificado!$B$2:$B$77,MATCH(SMALL(Modelo_final_tipificado!$E$2:$E$77,8),Modelo_final_tipificado!$E$2:$E$77,0)) -> MNG | G32: =SMALL(Modelo_final_tipificado!$E$2:$E$77,8) -> 66.749047 | I32: =INDEX(Modelo_final_tipificado!$A$2:$A$77,MATCH(LARGE(Modelo_final_tipificado!$F$2:$F$77,8),Modelo_final_tipificado!$F$2:$F$77,0)) -> Kenya | J32: =INDEX(Modelo_final_tipificado!$B$2:$B$77,MATCH(LARGE(Modelo_final_tipificado!$F$2:$F$77,8),Modelo_final_tipificado!$F$2:$F$77,0)) -> KEN | K32: =LARGE(Modelo_final_tipificado!$F$2:$F$77,8) -> 1.1459253
A33: =INDEX(Modelo_final_tipificado!$A$2:$A$77,MATCH(LARGE(Modelo_final_tipificado!$E$2:$E$77,9),Modelo_final_tipificado!$E$2:$E$77,0)) -> Poland | B33: =INDEX(Modelo_final_tipificado!$B$2:$B$77,MATCH(LARGE(Modelo_final_tipificado!$E$2:$E$77,9),Modelo_final_tipificado!$E$2:$E$77,0)) -> POL | C33: =LARGE(Modelo_final_tipificado!$E$2:$E$77,9) -> 82.082901 | E33: =INDEX(Modelo_final_tipificado!$A$2:$A$77,MATCH(SMALL(Modelo_final_tipificado!$E$2:$E$77,9),Modelo_final_tipificado!$E$2:$E$77,0)) -> India | F33: =INDEX(Modelo_final_tipificado!$B$2:$B$77,MATCH(SMALL(Modelo_final_tipificado!$E$2:$E$77,9),Modelo_final_tipificado!$E$2:$E$77,0)) -> IND | G33: =SMALL(Modelo_final_tipificado!$E$2:$E$77,9) -> 66.954602 | I33: =INDEX(Modelo_final_tipificado!$A$2:$A$77,MATCH(LARGE(Modelo_final_tipificado!$F$2:$F$77,9),Modelo_final_tipificado!$F$2:$F$77,0)) -> Ukraine | J33: =INDEX(Modelo_final_tipificado!$B$2:$B$77,MATCH(LARGE(Modelo_final_tipificado!$F$2:$F$77,9),Modelo_final_tipificado!$F$2:$F$77,0)) -> UKR | K33: =LARGE(Modelo_final_tipificado!$F$2:$F$77,9) -> 1.128064
A34: =INDEX(Modelo_final_tipificado!$A$2:$A$77,MATCH(LARGE(Modelo_final_tipificado!$E$2:$E$77,10),Modelo_final_tipificado!$E$2:$E$77,0)) -> Czechia | B34: =INDEX(Modelo_final_tipificado!$B$2:$B$77,MATCH(LARGE(Modelo_final_tipificado!$E$2:$E$77,10),Modelo_final_tipificado!$E$2:$E$77,0)) -> CZE | C34: =LARGE(Modelo_final_tipificado!$E$2:$E$77,10) -> 81.93561 | E34: =INDEX(Modelo_final_tipificado!$A$2:$A$77,MATCH(SMALL(Modelo_final_tipificado!$E$2:$E$77,10),Modelo_final_tipificado!$E$2:$E$77,0)) -> Egypt, Arab Rep. | F34: =INDEX(Modelo_final_tipificado!$B$2:$B$77,MATCH(SMALL(Modelo_final_tipificado!$E$2:$E$77,10),Modelo_final_tipificado!$E$2:$E$77,0)) -> EGY | G34: =SMALL(Modelo_final_tipificado!$E$2:$E$77,10) -> 68.09105 | I34: =INDEX(Modelo_final_tipificado!$A$2:$A$77,MATCH(LARGE(Modelo_final_tipificado!$F$2:$F$77,10),Modelo_final_tipificado!$F$2:$F$77,0)) -> Lithuania | J34: =INDEX(Modelo_final_tipificado!$B$2:$B$77,MATCH(LARGE(Modelo_final_tipificado!$F$2:$F$77,10),Modelo_final_tipificado!$F$2:$F$77,0)) -> LTU | K34: =LARGE(Modelo_final_tipificado!$F$2:$F$77,10) -> 1.1181926
A37: Matriz de correlaciones
A38: Variable | B38: SDG INDEX | C38: SDG INDEX 2021 | D38: SDG INDEX 2025 | E38: SDG INDEX 2025 - 2021 | F38: z_ln_GDP_per_capita_PPP | G38: z_Government_Effectiveness | H38: z_Education_expenditure_pct_GDP | I38: z_ln_Patents_per_million_plus_1 | J38: z_Research_expenditure_pct_GDP | K38: z_Trade_pct_GDP
A39: SDG INDEX | B39: =CORREL(Modelo_final_tipificado!C2:C77,Modelo_final_tipificado!C2:C77) -> 1 | C39: =CORREL(Modelo_final_tipificado!C2:C77,Modelo_final_tipificado!D2:D77) -> 0.98732366 | D39: =CORREL(Modelo_final_tipificado!C2:C77,Modelo_final_tipificado!E2:E77) -> 0.98427507 | E39: =CORREL(Modelo_final_tipificado!C2:C77,Modelo_final_tipificado!F2:F77) -> -0.33127251 | F39: =CORREL(Modelo_final_tipificado!C2:C77,Modelo_final_tipificado!G2:G77) -> 0.82458551 | G39: =CORREL(Modelo_final_tipificado!C2:C77,Modelo_final_tipificado!H2:H77) -> 0.70815389 | H39: =CORREL(Modelo_final_tipificado!C2:C77,Modelo_final_tipificado!I2:I77) -> 0.55043987 | I39: =CORREL(Modelo_final_tipificado!C2:C77,Modelo_final_tipificado!J2:J77) -> 0.74327238 | J39: =CORREL(Modelo_final_tipificado!C2:C77,Modelo_final_tipificado!K2:K77) -> 0.60535605 | K39: =CORREL(Modelo_final_tipificado!C2:C77,Modelo_final_tipificado!L2:L77) -> 0.23171262
A40: SDG INDEX 2021 | B40: =CORREL(Modelo_final_tipificado!D2:D77,Modelo_final_tipificado!C2:C77) -> 0.98732366 | C40: =CORREL(Modelo_final_tipificado!D2:D77,Modelo_final_tipificado!D2:D77) -> 1 | D40: =CORREL(Modelo_final_tipificado!D2:D77,Modelo_final_tipificado!E2:E77) -> 0.99644171 | E40: =CORREL(Modelo_final_tipificado!D2:D77,Modelo_final_tipificado!F2:F77) -> -0.34077451 | F40: =CORREL(Modelo_final_tipificado!D2:D77,Modelo_final_tipificado!G2:G77) -> 0.77963624 | G40: =CORREL(Modelo_final_tipificado!D2:D77,Modelo_final_tipificado!H2:H77) -> 0.65718694 | H40: =CORREL(Modelo_final_tipificado!D2:D77,Modelo_final_tipificado!I2:I77) -> 0.5244942 | I40: =CORREL(Modelo_final_tipificado!D2:D77,Modelo_final_tipificado!J2:J77) -> 0.72275673 | J40: =CORREL(Modelo_final_tipificado!D2:D77,Modelo_final_tipificado!K2:K77) -> 0.55427537 | K40: =CORREL(Modelo_final_tipificado!D2:D77,Modelo_final_tipificado!L2:L77) -> 0.19769869
A41: SDG INDEX 2025 | B41: =CORREL(Modelo_final_tipificado!E2:E77,Modelo_final_tipificado!C2:C77) -> 0.98427507 | C41: =CORREL(Modelo_final_tipificado!E2:E77,Modelo_final_tipificado!D2:D77) -> 0.99644171 | D41: =CORREL(Modelo_final_tipificado!E2:E77,Modelo_final_tipificado!E2:E77) -> 1 | E41: =CORREL(Modelo_final_tipificado!E2:E77,Modelo_final_tipificado!F2:F77) -> -0.26032205 | F41: =CORREL(Modelo_final_tipificado!E2:E77,Modelo_final_tipificado!G2:G77) -> 0.7874896 | G41: =CORREL(Modelo_final_tipificado!E2:E77,Modelo_final_tipificado!H2:H77) -> 0.67339335 | H41: =CORREL(Modelo_final_tipificado!E2:E77,Modelo_final_tipificado!I2:I77) -> 0.52936382 | I41: =CORREL(Modelo_final_tipificado!E2:E77,Modelo_final_tipificado!J2:J77) -> 0.72433914 | J41: =CORREL(Modelo_final_tipificado!E2:E77,Modelo_final_tipificado!K2:K77) -> 0.5563751 | K41: =CORREL(Modelo_final_tipificado!E2:E77,Modelo_final_tipificado!L2:L77) -> 0.21517124
A42: SDG INDEX 2025 - 2021 | B42: =CORREL(Modelo_final_tipificado!F2:F77,Modelo_final_tipificado!C2:C77) -> -0.33127251 | C42: =CORREL(Modelo_final_tipificado!F2:F77,Modelo_final_tipificado!D2:D77) -> -0.34077451 | D42: =CORREL(Modelo_final_tipificado!F2:F77,Modelo_final_tipificado!E2:E77) -> -0.26032205 | E42: =CORREL(Modelo_final_tipificado!F2:F77,Modelo_final_tipificado!F2:F77) -> 1 | F42: =CORREL(Modelo_final_tipificado!F2:F77,Modelo_final_tipificado!G2:G77) -> -0.14713658 | G42: =CORREL(Modelo_final_tipificado!F2:F77,Modelo_final_tipificado!H2:H77) -> -0.017095777 | H42: =CORREL(Modelo_final_tipificado!F2:F77,Modelo_final_tipificado!I2:I77) -> -0.10356961 | I42: =CORREL(Modelo_final_tipificado!F2:F77,Modelo_final_tipificado!J2:J77) -> -0.19995963 | J42: =CORREL(Modelo_final_tipificado!F2:F77,Modelo_final_tipificado!K2:K77) -> -0.14173909 | K42: =CORREL(Modelo_final_tipificado!F2:F77,Modelo_final_tipificado!L2:L77) -> 0.1353718
A43: z_ln_GDP_per_capita_PPP | B43: =CORREL(Modelo_final_tipificado!G2:G77,Modelo_final_tipificado!C2:C77) -> 0.82458551 | C43: =CORREL(Modelo_final_tipificado!G2:G77,Modelo_final_tipificado!D2:D77) -> 0.77963624 | D43: =CORREL(Modelo_final_tipificado!G2:G77,Modelo_final_tipificado!E2:E77) -> 0.7874896 | E43: =CORREL(Modelo_final_tipificado!G2:G77,Modelo_final_tipificado!F2:F77) -> -0.14713658 | F43: =CORREL(Modelo_final_tipificado!G2:G77,Modelo_final_tipificado!G2:G77) -> 1 | G43: =CORREL(Modelo_final_tipificado!G2:G77,Modelo_final_tipificado!H2:H77) -> 0.8606023 | H43: =CORREL(Modelo_final_tipificado!G2:G77,Modelo_final_tipificado!I2:I77) -> 0.43783616 | I43: =CORREL(Modelo_final_tipificado!G2:G77,Modelo_final_tipificado!J2:J77) -> 0.73753968 | J43: =CORREL(Modelo_final_tipificado!G2:G77,Modelo_final_tipificado!K2:K77) -> 0.67797805 | K43: =CORREL(Modelo_final_tipificado!G2:G77,Modelo_final_tipificado!L2:L77) -> 0.41212235
A44: z_Government_Effectiveness | B44: =CORREL(Modelo_final_tipificado!H2:H77,Modelo_final_tipificado!C2:C77) -> 0.70815389 | C44: =CORREL(Modelo_final_tipificado!H2:H77,Modelo_final_tipificado!D2:D77) -> 0.65718694 | D44: =CORREL(Modelo_final_tipificado!H2:H77,Modelo_final_tipificado!E2:E77) -> 0.67339335 | E44: =CORREL(Modelo_final_tipificado!H2:H77,Modelo_final_tipificado!F2:F77) -> -0.017095777 | F44: =CORREL(Modelo_final_tipificado!H2:H77,Modelo_final_tipificado!G2:G77) -> 0.8606023 | G44: =CORREL(Modelo_final_tipificado!H2:H77,Modelo_final_tipificado!H2:H77) -> 1 | H44: =CORREL(Modelo_final_tipificado!H2:H77,Modelo_final_tipificado!I2:I77) -> 0.49332434 | I44: =CORREL(Modelo_final_tipificado!H2:H77,Modelo_final_tipificado!J2:J77) -> 0.65940916 | J44: =CORREL(Modelo_final_tipificado!H2:H77,Modelo_final_tipificado!K2:K77) -> 0.7870024 | K44: =CORREL(Modelo_final_tipificado!H2:H77,Modelo_final_tipificado!L2:L77) -> 0.38137479
A45: z_Education_expenditure_pct_GDP | B45: =CORREL(Modelo_final_tipificado!I2:I77,Modelo_final_tipificado!C2:C77) -> 0.55043987 | C45: =CORREL(Modelo_final_tipificado!I2:I77,Modelo_final_tipificado!D2:D77) -> 0.5244942 | D45: =CORREL(Modelo_final_tipificado!I2:I77,Modelo_final_tipificado!E2:E77) -> 0.52936382 | E45: =CORREL(Modelo_final_tipificado!I2:I77,Modelo_final_tipificado!F2:F77) -> -0.10356961 | F45: =CORREL(Modelo_final_tipificado!I2:I77,Modelo_final_tipificado!G2:G77) -> 0.43783616 | G45: =CORREL(Modelo_final_tipificado!I2:I77,Modelo_final_tipificado!H2:H77) -> 0.49332434 | H45: =CORREL(Modelo_final_tipificado!I2:I77,Modelo_final_tipificado!I2:I77) -> 1 | I45: =CORREL(Modelo_final_tipificado!I2:I77,Modelo_final_tipificado!J2:J77) -> 0.41041934 | J45: =CORREL(Modelo_final_tipificado!I2:I77,Modelo_final_tipificado!K2:K77) -> 0.48706469 | K45: =CORREL(Modelo_final_tipificado!I2:I77,Modelo_final_tipificado!L2:L77) -> 0.094889871
A46: z_ln_Patents_per_million_plus_1 | B46: =CORREL(Modelo_final_tipificado!J2:J77,Modelo_final_tipificado!C2:C77) -> 0.74327238 | C46: =CORREL(Modelo_final_tipificado!J2:J77,Modelo_final_tipificado!D2:D77) -> 0.72275673 | D46: =CORREL(Modelo_final_tipificado!J2:J77,Modelo_final_tipificado!E2:E77) -> 0.72433914 | E46: =CORREL(Modelo_final_tipificado!J2:J77,Modelo_final_tipificado!F2:F77) -> -0.19995963 | F46: =CORREL(Modelo_final_tipificado!J2:J77,Modelo_final_tipificado!G2:G77) -> 0.73753968 | G46: =CORREL(Modelo_final_tipificado!J2:J77,Modelo_final_tipificado!H2:H77) -> 0.65940916 | H46: =CORREL(Modelo_final_tipificado!J2:J77,Modelo_final_tipificado!I2:I77) -> 0.41041934 | I46: =CORREL(Modelo_final_tipificado!J2:J77,Modelo_final_tipificado!J2:J77) -> 1 | J46: =CORREL(Modelo_final_tipificado!J2:J77,Modelo_final_tipificado!K2:K77) -> 0.78911246 | K46: =CORREL(Modelo_final_tipificado!J2:J77,Modelo_final_tipificado!L2:L77) -> 0.17109655
...

Sheet Info_Datos
A1: Paso | B1: Descripción
A2: 1 | B2: Base de partida: países filtrados con regla de relevancia 75% en al menos 5 de 6 variables.
A3: 2 | B3: Se utilizan variables agregadas
A4: 3 | B4: Se añadió la diferencia "SDG INDEX 2025 - 2021".
A5: 4 | B5: Se construyó "Patents per million inhabitants" = patentes medias / población media * 1.000.000.
A6: 5 | B6: Transformación logarítmica aplicada a GDP per capita PPP y a Patents per million + 1.
A7: 6 | B7: Finalmente, las 6 variables explicativas se tipifican
A9: Variable evaluada | B9: Log | C9: Estandarización
A10: ln GDP per capita PPP | B10: Sí | C10: Sí
A11: Government Effectiveness: Estimate | B11: No | C11: Sí
A12: Government expenditure on education, total (% of GDP) | B12: No | C12: Sí
A13: ln Patents per million + 1 | B13: Sí | C13: Sí
A14: Research and development expenditure (% of GDP) | B14: No | C14: Sí
A15: Trade (% of GDP) | B15: No | C15: Sí
A17: Nota versión final
